<sdf version='1.7'>
  <world name='mdp_greenhouse'>
    <gravity>0 0 -9.8066</gravity>
    <physics name='default_physics' type='ode'>
      <max_step_size>0.001</max_step_size>
      <real_time_factor>1</real_time_factor>
      <real_time_update_rate>1000</real_time_update_rate>
    </physics>
    <scene>
      <ambient>0.55 0.58 0.55 1</ambient>
      <background>0.78 0.84 0.88 1</background>
      <shadows>1</shadows>
    </scene>
    <light name='sun' type='directional'>
      <cast_shadows>1</cast_shadows>
      <pose>2.5 5 10 0 -0 0</pose>
      <diffuse>0.8 0.8 0.75 1</diffuse>
      <specular>0.2 0.2 0.2 1</specular>
      <direction>-0.25 0.45 -1</direction>
      <attenuation>
        <range>10</range>
      </attenuation>
      <spot>
        <inner_angle>0</inner_angle>
        <outer_angle>0</outer_angle>
        <falloff>0</falloff>
      </spot>
    </light>
    <model name='mdp_greenhouse_environment'>
      <static>1</static>
      <link name='floor'>
        <pose>2.5 5 -0.01 0 -0 0</pose>
        <collision name='collision'>
          <geometry>
            <box>
              <size>5 10 0.02</size>
            </box>
          </geometry>
          <max_contacts>10</max_contacts>
          <surface>
            <contact>
              <ode/>
            </contact>
            <bounce/>
            <friction>
              <torsional>
                <ode/>
              </torsional>
              <ode/>
            </friction>
          </surface>
        </collision>
        <visual name='visual'>
          <geometry>
            <box>
              <size>5 10 0.02</size>
            </box>
          </geometry>
          <material>
            <ambient>0.47 0.54 0.5 1</ambient>
            <diffuse>0.47 0.54 0.5 1</diffuse>
          </material>
        </visual>
        <self_collide>0</self_collide>
        <enable_wind>0</enable_wind>
        <kinematic>0</kinematic>
      </link>
      <link name='west_wall'>
        <pose>-0.04 5 0.75 0 -0 0</pose>
        <collision name='collision'>
          <geometry>
            <box>
              <size>0.08 10.16 1.5</size>
            </box>
          </geometry>
          <max_contacts>10</max_contacts>
          <surface>
            <contact>
              <ode/>
            </contact>
            <bounce/>
            <friction>
              <torsional>
                <ode/>
              </torsional>
              <ode/>
            </friction>
          </surface>
        </collision>
        <visual name='visual'>
          <geometry>
            <box>
              <size>0.08 10.16 1.5</size>
            </box>
          </geometry>
          <material>
            <ambient>0.28 0.42 0.36 1</ambient>
            <diffuse>0.28 0.42 0.36 1</diffuse>
          </material>
        </visual>
        <self_collide>0</self_collide>
        <enable_wind>0</enable_wind>
        <kinematic>0</kinematic>
      </link>
      <link name='east_wall'>
        <pose>5.04 5 0.75 0 -0 0</pose>
        <collision name='collision'>
          <geometry>
            <box>
              <size>0.08 10.16 1.5</size>
            </box>
          </geometry>
          <max_contacts>10</max_contacts>
          <surface>
            <contact>
              <ode/>
            </contact>
            <bounce/>
            <friction>
              <torsional>
                <ode/>
              </torsional>
              <ode/>
            </friction>
          </surface>
        </collision>
        <visual name='visual'>
          <geometry>
            <box>
              <size>0.08 10.16 1.5</size>
            </box>
          </geometry>
          <material>
            <ambient>0.28 0.42 0.36 1</ambient>
            <diffuse>0.28 0.42 0.36 1</diffuse>
          </material>
        </visual>
        <self_collide>0</self_collide>
        <enable_wind>0</enable_wind>
        <kinematic>0</kinematic>
      </link>
      <link name='south_wall'>
        <pose>2.5 -0.04 0.75 0 -0 0</pose>
        <collision name='collision'>
          <geometry>
            <box>
              <size>5.16 0.08 1.5</size>
            </box>
          </geometry>
          <max_contacts>10</max_contacts>
          <surface>
            <contact>
              <ode/>
            </contact>
            <bounce/>
            <friction>
              <torsional>
                <ode/>
              </torsional>
              <ode/>
            </friction>
          </surface>
        </collision>
        <visual name='visual'>
          <geometry>
            <box>
              <size>5.16 0.08 1.5</size>
            </box>
          </geometry>
          <material>
            <ambient>0.28 0.42 0.36 1</ambient>
            <diffuse>0.28 0.42 0.36 1</diffuse>
          </material>
        </visual>
        <self_collide>0</self_collide>
        <enable_wind>0</enable_wind>
        <kinematic>0</kinematic>
      </link>
      <link name='north_wall'>
        <pose>2.5 10.04 0.75 0 -0 0</pose>
        <collision name='collision'>
          <geometry>
            <box>
              <size>5.16 0.08 1.5</size>
            </box>
          </geometry>
          <max_contacts>10</max_contacts>
          <surface>
            <contact>
              <ode/>
            </contact>
            <bounce/>
            <friction>
              <torsional>
                <ode/>
              </torsional>
              <ode/>
            </friction>
          </surface>
        </collision>
        <visual name='visual'>
          <geometry>
            <box>
              <size>5.16 0.08 1.5</size>
            </box>
          </geometry>
          <material>
            <ambient>0.28 0.42 0.36 1</ambient>
            <diffuse>0.28 0.42 0.36 1</diffuse>
          </material>
        </visual>
        <self_collide>0</self_collide>
        <enable_wind>0</enable_wind>
        <kinematic>0</kinematic>
      </link>
      <link name='table_1'>
        <pose>1.25 2.025 0.375 0 -0 0</pose>
        <collision name='collision'>
          <geometry>
            <box>
              <size>1.1 0.25 0.19</size>
            </box>
          </geometry>
          <max_contacts>10</max_contacts>
          <surface>
            <contact>
              <ode/>
            </contact>
            <bounce/>
            <friction>
              <torsional>
                <ode/>
              </torsional>
              <ode/>
            </friction>
          </surface>
        </collision>
        <visual name='visual'>
          <geometry>
            <box>
              <size>1.1 0.25 0.19</size>
            </box>
          </geometry>
          <material>
            <ambient>0.34 0.48 0.29 1</ambient>
            <diffuse>0.34 0.48 0.29 1</diffuse>
          </material>
        </visual>
        <self_collide>0</self_collide>
        <enable_wind>0</enable_wind>
        <kinematic>0</kinematic>
      </link>
      <link name='table_2'>
        <pose>3.55 2.025 0.375 0 -0 0</pose>
        <collision name='collision'>
          <geometry>
            <box>
              <size>1.1 0.25 0.19</size>
            </box>
          </geometry>
          <max_contacts>10</max_contacts>
          <surface>
            <contact>
              <ode/>
            </contact>
            <bounce/>
            <friction>
              <torsional>
                <ode/>
              </torsional>
              <ode/>
            </friction>
          </surface>
        </collision>
        <visual name='visual'>
          <geometry>
            <box>
              <size>1.1 0.25 0.19</size>
            </box>
          </geometry>
          <material>
            <ambient>0.34 0.48 0.29 1</ambient>
            <diffuse>0.34 0.48 0.29 1</diffuse>
          </material>
        </visual>
        <self_collide>0</self_collide>
        <enable_wind>0</enable_wind>
        <kinematic>0</kinematic>
      </link>
      <link name='table_3'>
        <pose>1.25 3.025 0.375 0 -0 0</pose>
        <collision name='collision'>
          <geometry>
            <box>
              <size>1.1 0.25 0.19</size>
            </box>
          </geometry>
          <max_contacts>10</max_contacts>
          <surface>
            <contact>
              <ode/>
            </contact>
            <bounce/>
            <friction>
              <torsional>
                <ode/>
              </torsional>
              <ode/>
            </friction>
          </surface>
        </collision>
        <visual name='visual'>
          <geometry>
            <box>
              <size>1.1 0.25 0.19</size>
            </box>
          </geometry>
          <material>
            <ambient>0.34 0.48 0.29 1</ambient>
            <diffuse>0.34 0.48 0.29 1</diffuse>
          </material>
        </visual>
        <self_collide>0</self_collide>
        <enable_wind>0</enable_wind>
        <kinematic>0</kinematic>
      </link>
      <link name='table_4'>
        <pose>3.55 3.025 0.375 0 -0 0</pose>
        <collision name='collision'>
          <geometry>
            <box>
              <size>1.1 0.25 0.19</size>
            </box>
          </geometry>
          <max_contacts>10</max_contacts>
          <surface>
            <contact>
              <ode/>
            </contact>
            <bounce/>
            <friction>
              <torsional>
                <ode/>
              </torsional>
              <ode/>
            </friction>
          </surface>
        </collision>
        <visual name='visual'>
          <geometry>
            <box>
              <size>1.1 0.25 0.19</size>
            </box>
          </geometry>
          <material>
            <ambient>0.34 0.48 0.29 1</ambient>
            <diffuse>0.34 0.48 0.29 1</diffuse>
          </material>
        </visual>
        <self_collide>0</self_collide>
        <enable_wind>0</enable_wind>
        <kinematic>0</kinematic>
      </link>
      <link name='table_5'>
        <pose>1.35 4.025 0.375 0 -0 0</pose>
        <collision name='collision'>
          <geometry>
            <box>
              <size>1.1 0.25 0.19</size>
            </box>
          </geometry>
          <max_contacts>10</max_contacts>
          <surface>
            <contact>
              <ode/>
            </contact>
            <bounce/>
            <friction>
              <torsional>
                <ode/>
              </torsional>
              <ode/>
            </friction>
          </surface>
        </collision>
        <visual name='visual'>
          <geometry>
            <box>
              <size>1.1 0.25 0.19</size>
            </box>
          </geometry>
          <material>
            <ambient>0.34 0.48 0.29 1</ambient>
            <diffuse>0.34 0.48 0.29 1</diffuse>
          </material>
        </visual>
        <self_collide>0</self_collide>
        <enable_wind>0</enable_wind>
        <kinematic>0</kinematic>
      </link>
      <link name='table_6'>
        <pose>3.55 4.025 0.375 0 -0 0</pose>
        <collision name='collision'>
          <geometry>
            <box>
              <size>1.1 0.25 0.19</size>
            </box>
          </geometry>
          <max_contacts>10</max_contacts>
          <surface>
            <contact>
              <ode/>
            </contact>
            <bounce/>
            <friction>
              <torsional>
                <ode/>
              </torsional>
              <ode/>
            </friction>
          </surface>
        </collision>
        <visual name='visual'>
          <geometry>
            <box>
              <size>1.1 0.25 0.19</size>
            </box>
          </geometry>
          <material>
            <ambient>0.34 0.48 0.29 1</ambient>
            <diffuse>0.34 0.48 0.29 1</diffuse>
          </material>
        </visual>
        <self_collide>0</self_collide>
        <enable_wind>0</enable_wind>
        <kinematic>0</kinematic>
      </link>
      <link name='table_7'>
        <pose>0.925 5.55 0.375 0 -0 0</pose>
        <collision name='collision'>
          <geometry>
            <box>
              <size>0.25 1.1 0.19</size>
            </box>
          </geometry>
          <max_contacts>10</max_contacts>
          <surface>
            <contact>
              <ode/>
            </contact>
            <bounce/>
            <friction>
              <torsional>
                <ode/>
              </torsional>
              <ode/>
            </friction>
          </surface>
        </collision>
        <visual name='visual'>
          <geometry>
            <box>
              <size>0.25 1.1 0.19</size>
            </box>
          </geometry>
          <material>
            <ambient>0.34 0.48 0.29 1</ambient>
            <diffuse>0.34 0.48 0.29 1</diffuse>
          </material>
        </visual>
        <self_collide>0</self_collide>
        <enable_wind>0</enable_wind>
        <kinematic>0</kinematic>
      </link>
      <link name='table_8'>
        <pose>2.325 5.55 0.375 0 -0 0</pose>
        <collision name='collision'>
          <geometry>
            <box>
              <size>0.25 1.1 0.19</size>
            </box>
          </geometry>
          <max_contacts>10</max_contacts>
          <surface>
            <contact>
              <ode/>
            </contact>
            <bounce/>
            <friction>
              <torsional>
                <ode/>
              </torsional>
              <ode/>
            </friction>
          </surface>
        </collision>
        <visual name='visual'>
          <geometry>
            <box>
              <size>0.25 1.1 0.19</size>
            </box>
          </geometry>
          <material>
            <ambient>0.34 0.48 0.29 1</ambient>
            <diffuse>0.34 0.48 0.29 1</diffuse>
          </material>
        </visual>
        <self_collide>0</self_collide>
        <enable_wind>0</enable_wind>
        <kinematic>0</kinematic>
      </link>
      <link name='table_9'>
        <pose>3.525 5.55 0.375 0 -0 0</pose>
        <collision name='collision'>
          <geometry>
            <box>
              <size>0.25 1.1 0.19</size>
            </box>
          </geometry>
          <max_contacts>10</max_contacts>
          <surface>
            <contact>
              <ode/>
            </contact>
            <bounce/>
            <friction>
              <torsional>
                <ode/>
              </torsional>
              <ode/>
            </friction>
          </surface>
        </collision>
        <visual name='visual'>
          <geometry>
            <box>
              <size>0.25 1.1 0.19</size>
            </box>
          </geometry>
          <material>
            <ambient>0.34 0.48 0.29 1</ambient>
            <diffuse>0.34 0.48 0.29 1</diffuse>
          </material>
        </visual>
        <self_collide>0</self_collide>
        <enable_wind>0</enable_wind>
        <kinematic>0</kinematic>
      </link>
      <link name='table_10'>
        <pose>0.925 7.25 0.375 0 -0 0</pose>
        <collision name='collision'>
          <geometry>
            <box>
              <size>0.25 1.1 0.19</size>
            </box>
          </geometry>
          <max_contacts>10</max_contacts>
          <surface>
            <contact>
              <ode/>
            </contact>
            <bounce/>
            <friction>
              <torsional>
                <ode/>
              </torsional>
              <ode/>
            </friction>
          </surface>
        </collision>
        <visual name='visual'>
          <geometry>
            <box>
              <size>0.25 1.1 0.19</size>
            </box>
          </geometry>
          <material>
            <ambient>0.34 0.48 0.29 1</ambient>
            <diffuse>0.34 0.48 0.29 1</diffuse>
          </material>
        </visual>
        <self_collide>0</self_collide>
        <enable_wind>0</enable_wind>
        <kinematic>0</kinematic>
      </link>
      <link name='table_11'>
        <pose>2.325 7.25 0.375 0 -0 0</pose>
        <collision name='collision'>
          <geometry>
            <box>
              <size>0.25 1.1 0.19</size>
            </box>
          </geometry>
          <max_contacts>10</max_contacts>
          <surface>
            <contact>
              <ode/>
            </contact>
            <bounce/>
            <friction>
              <torsional>
                <ode/>
              </torsional>
              <ode/>
            </friction>
          </surface>
        </collision>
        <visual name='visual'>
          <geometry>
            <box>
              <size>0.25 1.1 0.19</size>
            </box>
          </geometry>
          <material>
            <ambient>0.34 0.48 0.29 1</ambient>
            <diffuse>0.34 0.48 0.29 1</diffuse>
          </material>
        </visual>
        <self_collide>0</self_collide>
        <enable_wind>0</enable_wind>
        <kinematic>0</kinematic>
      </link>
      <link name='table_12'>
        <pose>3.525 7.25 0.375 0 -0 0</pose>
        <collision name='collision'>
          <geometry>
            <box>
              <size>0.25 1.1 0.19</size>
            </box>
          </geometry>
          <max_contacts>10</max_contacts>
          <surface>
            <contact>
              <ode/>
            </contact>
            <bounce/>
            <friction>
              <torsional>
                <ode/>
              </torsional>
              <ode/>
            </friction>
          </surface>
        </collision>
        <visual name='visual'>
          <geometry>
            <box>
              <size>0.25 1.1 0.19</size>
            </box>
          </geometry>
          <material>
            <ambient>0.34 0.48 0.29 1</ambient>
            <diffuse>0.34 0.48 0.29 1</diffuse>
          </material>
        </visual>
        <self_collide>0</self_collide>
        <enable_wind>0</enable_wind>
        <kinematic>0</kinematic>
      </link>
    </model>
    <magnetic_field>6e-06 2.3e-05 -4.2e-05</magnetic_field>
    <atmosphere type='adiabatic'/>
    <audio>
      <device>default</device>
    </audio>
    <wind/>
    <spherical_coordinates>
      <surface_model>EARTH_WGS84</surface_model>
      <latitude_deg>0</latitude_deg>
      <longitude_deg>0</longitude_deg>
      <elevation>0</elevation>
      <heading_deg>0</heading_deg>
    </spherical_coordinates>
    <model name='mirte'>
      <link name='base_link'>
        <inertial>
          <pose>0.009156 -0.000463 0.064057 0 -0 0</pose>
          <mass>5.66551</mass>
          <inertia>
            <ixx>0.0232546</ixx>
            <ixy>0.000172283</ixy>
            <ixz>-0.00591328</ixz>
            <iyy>0.0505255</iyy>
            <iyz>7.96317e-05</iyz>
            <izz>0.0647626</izz>
          </inertia>
        </inertial>
        <collision name='base_link_fixed_joint_lump__frame_link_collision'>
          <pose>0 0 0.07 0 -0 1.5708</pose>
          <geometry>
            <box>
              <size>0.19 0.28 0.06</size>
            </box>
          </geometry>
          <max_contacts>10</max_contacts>
          <surface>
            <contact>
              <ode/>
            </contact>
            <bounce/>
            <friction>
              <torsional>
                <ode/>
              </torsional>
              <ode/>
            </friction>
          </surface>
        </collision>
        <collision name='base_link_fixed_joint_lump__frame_link_collision_1'>
          <pose>-0.05 0 0.145 0 -0 1.5708</pose>
          <geometry>
            <box>
              <size>0.18 0.16 0.05</size>
            </box>
          </geometry>
          <max_contacts>10</max_contacts>
          <surface>
            <contact>
              <ode/>
            </contact>
            <bounce/>
            <friction>
              <torsional>
                <ode/>
              </torsional>
              <ode/>
            </friction>
          </surface>
        </collision>
        <collision name='base_link_fixed_joint_lump__frame_link_collision_2'>
          <pose>0.002558 -0.062156 0.1125 0 -0 2.13803</pose>
          <geometry>
            <box>
              <size>0.013 0.03 0.025</size>
            </box>
          </geometry>
          <max_contacts>10</max_contacts>
          <surface>
            <contact>
              <ode/>
            </contact>
            <bounce/>
            <friction>
              <torsional>
                <ode/>
              </torsional>
              <ode/>
            </friction>
          </surface>
        </collision>
        <collision name='base_link_fixed_joint_lump__frame_link_collision_3'>
          <pose>-0.001664 0.064835 0.1125 0 -0 1.00356</pose>
          <geometry>
            <box>
              <size>0.013 0.04 0.025</size>
            </box>
          </geometry>
          <max_contacts>10</max_contacts>
          <surface>
            <contact>
              <ode/>
            </contact>
            <bounce/>
            <friction>
              <torsional>
                <ode/>
              </torsional>
              <ode/>
            </friction>
          </surface>
        </collision>
        <collision name='base_link_fixed_joint_lump__camera_link_collision_4'>
          <pose>0.128359 -0.0025 0.1442 0 -0 0</pose>
          <geometry>
            <box>
              <size>0.037 0.165 0.035</size>
            </box>
          </geometry>
          <surface>
            <contact>
              <ode/>
            </contact>
            <friction>
              <ode/>
              <torsional>
                <ode/>
              </torsional>
            </friction>
            <bounce/>
          </surface>
          <max_contacts>10</max_contacts>
        </collision>
        <collision name='base_link_fixed_joint_lump__front_left_sonar_collision_5'>
          <pose>0.120282 0.052978 0.069 0 0 -1.27409</pose>
          <geometry>
            <box>
              <size>0.045 0.025 0.02</size>
            </box>
          </geometry>
          <surface>
            <contact>
              <ode/>
            </contact>
            <friction>
              <ode/>
              <torsional>
                <ode/>
              </torsional>
            </friction>
            <bounce/>
          </surface>
          <max_contacts>10</max_contacts>
        </collision>
        <collision name='base_link_fixed_joint_lump__front_right_sonar_collision_6'>
          <pose>0.120282 -0.052978 0.069 0 0 -1.8675</pose>
          <geometry>
            <box>
              <size>0.045 0.025 0.02</size>
            </box>
          </geometry>
          <surface>
            <contact>
              <ode/>
            </contact>
            <friction>
              <ode/>
              <torsional>
                <ode/>
              </torsional>
            </friction>
            <bounce/>
          </surface>
          <max_contacts>10</max_contacts>
        </collision>
        <collision name='base_link_fixed_joint_lump__rear_left_sonar_collision_7'>
          <pose>-0.119187 0.056561 0.069 0 -0 1.27409</pose>
          <geometry>
            <box>
              <size>0.045 0.025 0.02</size>
            </box>
          </geometry>
          <surface>
            <contact>
              <ode/>
            </contact>
            <friction>
              <ode/>
              <torsional>
                <ode/>
              </torsional>
            </friction>
            <bounce/>
          </surface>
          <max_contacts>10</max_contacts>
        </collision>
        <collision name='base_link_fixed_joint_lump__rear_right_sonar_collision_8'>
          <pose>-0.119187 -0.056561 0.069 0 -0 1.8675</pose>
          <geometry>
            <box>
              <size>0.045 0.025 0.02</size>
            </box>
          </geometry>
          <surface>
            <contact>
              <ode/>
            </contact>
            <friction>
              <ode/>
              <torsional>
                <ode/>
              </torsional>
            </friction>
            <bounce/>
          </surface>
          <max_contacts>10</max_contacts>
        </collision>
        <collision name='base_link_fixed_joint_lump__lidar_base_collision_9'>
          <pose>0.1005 -0 0.107211 -1.5708 -0 -0</pose>
          <geometry>
            <mesh>
              <scale>1 1 1</scale>
              <uri>model://mirte_master_description/meshes/lidar.STL</uri>
            </mesh>
          </geometry>
          <max_contacts>10</max_contacts>
          <surface>
            <contact>
              <ode/>
            </contact>
            <bounce/>
            <friction>
              <torsional>
                <ode/>
              </torsional>
              <ode/>
            </friction>
          </surface>
        </collision>
        <visual name='base_link_fixed_joint_lump__frame_link_visual'>
          <pose>0 0 0.1 0 -0 1.5708</pose>
          <geometry>
            <mesh>
              <scale>1 1 1</scale>
              <uri>model://mirte_master_description/meshes/frame_link.STL</uri>
            </mesh>
          </geometry>
        </visual>
        <visual name='base_link_fixed_joint_lump__camera_link_visual_1'>
          <pose>0.146659 -0.0025 0.1277 0 -0 0</pose>
          <geometry>
            <mesh>
              <scale>1 1 1</scale>
              <uri>model://mirte_master_description/meshes/orbbec_astra.stl</uri>
            </mesh>
          </geometry>
        </visual>
        <visual name='base_link_fixed_joint_lump__front_left_sonar_visual_2'>
          <pose>0.120282 0.052978 0.069 0 0 -1.27409</pose>
          <geometry>
            <mesh>
              <scale>1 1 1</scale>
              <uri>model://mirte_master_description/meshes/ultrasonic_fl.STL</uri>
            </mesh>
          </geometry>
        </visual>
        <visual name='base_link_fixed_joint_lump__front_right_sonar_visual_3'>
          <pose>0.120282 -0.052978 0.069 0 0 -1.8675</pose>
          <geometry>
            <mesh>
              <scale>1 1 1</scale>
              <uri>model://mirte_master_description/meshes/ultrasonic_fl.STL</uri>
            </mesh>
          </geometry>
        </visual>
        <visual name='base_link_fixed_joint_lump__rear_left_sonar_visual_4'>
          <pose>-0.119187 0.056561 0.069 0 -0 1.27409</pose>
          <geometry>
            <mesh>
              <scale>1 1 1</scale>
              <uri>model://mirte_master_description/meshes/ultrasonic_fl.STL</uri>
            </mesh>
          </geometry>
        </visual>
        <visual name='base_link_fixed_joint_lump__rear_right_sonar_visual_5'>
          <pose>-0.119187 -0.056561 0.069 0 -0 1.8675</pose>
          <geometry>
            <mesh>
              <scale>1 1 1</scale>
              <uri>model://mirte_master_description/meshes/ultrasonic_fl.STL</uri>
            </mesh>
          </geometry>
        </visual>
        <visual name='base_link_fixed_joint_lump__lidar_base_visual_6'>
          <pose>0.1005 -0 0.107211 -1.5708 -0 -0</pose>
          <geometry>
            <mesh>
              <scale>1 1 1</scale>
              <uri>model://mirte_master_description/meshes/lidar.STL</uri>
            </mesh>
          </geometry>
        </visual>
        <gravity>1</gravity>
        <kinematic>1</kinematic>
        <sensor name='camera' type='depth'>
          <visualize>1</visualize>
          <update_rate>60</update_rate>
          <camera name='RS_D455'>
            <horizontal_fov>1.0472</horizontal_fov>
            <image>
              <width>640</width>
              <height>480</height>
              <format>R8G8B8</format>
            </image>
            <clip>
              <near>0.05</near>
              <far>10</far>
            </clip>
          </camera>
          <plugin name='camera_controller' filename='libgazebo_ros_camera.so'>
            <baseline>0.1</baseline>
            <alwaysOn>1</alwaysOn>
            <updateRate>30</updateRate>
            <frame_name>camera_depth_optical_frame</frame_name>
            <pointCloudCutoff>0.6</pointCloudCutoff>
            <pointCloudCutoffMax>8.0</pointCloudCutoffMax>
            <distortionK1>0</distortionK1>
            <distortionK2>0</distortionK2>
            <distortionK3>0</distortionK3>
            <distortionT1>0</distortionT1>
            <distortionT2>0</distortionT2>
            <CxPrime>0</CxPrime>
            <Cx>0</Cx>
            <Cy>0</Cy>
            <focalLength>0</focalLength>
            <hackBaseline>0</hackBaseline>
          </plugin>
          <pose>0.146659 -0.0025 0.1277 0 -0 0</pose>
        </sensor>
        <sensor name='range_sensor_front_left' type='ray'>
          <visualize>1</visualize>
          <ray>
            <scan>
              <horizontal>
                <samples>2</samples>
                <resolution>1</resolution>
                <min_angle>-0.26</min_angle>
                <max_angle>0.26</max_angle>
              </horizontal>
              <vertical>
                <samples>2</samples>
                <resolution>1</resolution>
                <min_angle>-0.014835</min_angle>
                <max_angle>0.014835</max_angle>
              </vertical>
            </scan>
            <range>
              <min>0.03</min>
              <max>4</max>
              <resolution>0.01</resolution>
            </range>
            <noise>
              <type>gaussian</type>
              <mean>0</mean>
              <stddev>0.01</stddev>
            </noise>
          </ray>
          <update_rate>30</update_rate>
          <plugin name='gazebo_ros_range_controller_front_left' filename='libgazebo_ros_ray_sensor.so'>
            <ros>
              <namespace>/mirte</namespace>
              <remapping>~/out:=distance/front_left</remapping>
            </ros>
            <output_type>sensor_msgs/Range</output_type>
            <radiation_type>ultrasound</radiation_type>
          </plugin>
          <pose>0.120282 0.052978 0.069 0 -0 0.296706</pose>
        </sensor>
        <sensor name='range_sensor_front_right' type='ray'>
          <visualize>1</visualize>
          <ray>
            <scan>
              <horizontal>
                <samples>2</samples>
                <resolution>1</resolution>
                <min_angle>-0.26</min_angle>
                <max_angle>0.26</max_angle>
              </horizontal>
              <vertical>
                <samples>2</samples>
                <resolution>1</resolution>
                <min_angle>-0.014835</min_angle>
                <max_angle>0.014835</max_angle>
              </vertical>
            </scan>
            <range>
              <min>0.03</min>
              <max>4</max>
              <resolution>0.01</resolution>
            </range>
            <noise>
              <type>gaussian</type>
              <mean>0</mean>
              <stddev>0.01</stddev>
            </noise>
          </ray>
          <update_rate>30</update_rate>
          <plugin name='gazebo_ros_range_controller_front_right' filename='libgazebo_ros_ray_sensor.so'>
            <ros>
              <namespace>/mirte</namespace>
              <remapping>~/out:=distance/front_right</remapping>
            </ros>
            <output_type>sensor_msgs/Range</output_type>
            <radiation_type>ultrasound</radiation_type>
          </plugin>
          <pose>0.120282 -0.052978 0.069 0 0 -0.296706</pose>
        </sensor>
        <sensor name='range_sensor_rear_left' type='ray'>
          <visualize>1</visualize>
          <ray>
            <scan>
              <horizontal>
                <samples>2</samples>
                <resolution>1</resolution>
                <min_angle>-0.26</min_angle>
                <max_angle>0.26</max_angle>
              </horizontal>
              <vertical>
                <samples>2</samples>
                <resolution>1</resolution>
                <min_angle>-0.014835</min_angle>
                <max_angle>0.014835</max_angle>
              </vertical>
            </scan>
            <range>
              <min>0.03</min>
              <max>4</max>
              <resolution>0.01</resolution>
            </range>
            <noise>
              <type>gaussian</type>
              <mean>0</mean>
              <stddev>0.01</stddev>
            </noise>
          </ray>
          <update_rate>30</update_rate>
          <plugin name='gazebo_ros_range_controller_rear_left' filename='libgazebo_ros_ray_sensor.so'>
            <ros>
              <namespace>/mirte</namespace>
              <remapping>~/out:=distance/rear_left</remapping>
            </ros>
            <output_type>sensor_msgs/Range</output_type>
            <radiation_type>ultrasound</radiation_type>
          </plugin>
          <pose>-0.119187 0.056561 0.069 0 -0 2.84489</pose>
        </sensor>
        <sensor name='range_sensor_rear_right' type='ray'>
          <visualize>1</visualize>
          <ray>
            <scan>
              <horizontal>
                <samples>2</samples>
                <resolution>1</resolution>
                <min_angle>-0.26</min_angle>
                <max_angle>0.26</max_angle>
              </horizontal>
              <vertical>
                <samples>2</samples>
                <resolution>1</resolution>
                <min_angle>-0.014835</min_angle>
                <max_angle>0.014835</max_angle>
              </vertical>
            </scan>
            <range>
              <min>0.03</min>
              <max>4</max>
              <resolution>0.01</resolution>
            </range>
            <noise>
              <type>gaussian</type>
              <mean>0</mean>
              <stddev>0.01</stddev>
            </noise>
          </ray>
          <update_rate>30</update_rate>
          <plugin name='gazebo_ros_range_controller_rear_right' filename='libgazebo_ros_ray_sensor.so'>
            <ros>
              <namespace>/mirte</namespace>
              <remapping>~/out:=distance/rear_right</remapping>
            </ros>
            <output_type>sensor_msgs/Range</output_type>
            <radiation_type>ultrasound</radiation_type>
          </plugin>
          <pose>-0.119187 -0.056561 0.069 0 0 -2.84489</pose>
        </sensor>
        <sensor name='lidar' type='ray'>
          <visualize>1</visualize>
          <update_rate>10</update_rate>
          <ray>
            <scan>
              <horizontal>
                <samples>360</samples>
                <resolution>1</resolution>
                <min_angle>-3.14</min_angle>
                <max_angle>3.14</max_angle>
              </horizontal>
              <vertical>
                <samples>1</samples>
                <min_angle>0</min_angle>
                <max_angle>0</max_angle>
              </vertical>
            </scan>
            <range>
              <min>0.03</min>
              <max>12</max>
              <resolution>0.01</resolution>
            </range>
          </ray>
          <plugin name='laser_controller' filename='libgazebo_ros_ray_sensor.so'>
            <ros>
              <remapping>~/out:=scan</remapping>
            </ros>
            <output_type>sensor_msgs/LaserScan</output_type>
            <frame_name>lidar_link</frame_name>
          </plugin>
          <pose>0.1005 -0 0.107211 -0 -0 -0</pose>
        </sensor>
        <gravity>1</gravity>
        <sensor name='imu_sensor' type='imu'>
          <always_on>1</always_on>
          <update_rate>100</update_rate>
          <visualize>1</visualize>
          <topic>__default_topic__</topic>
          <plugin name='imu_plugin' filename='libgazebo_ros_imu_sensor.so'>
            <topicName>imu</topicName>
            <bodyName>imu_link</bodyName>
            <updateRateHZ>10.0</updateRateHZ>
            <gaussianNoise>0.0</gaussianNoise>
            <xyzOffset>0 0 0</xyzOffset>
            <rpyOffset>0 0 0</rpyOffset>
            <frameName>imu_link</frameName>
            <initialOrientationAsReference>0</initialOrientationAsReference>
          </plugin>
          <pose>0 0 0.1 0 -0 0</pose>
          <imu/>
        </sensor>
        <self_collide>0</self_collide>
        <enable_wind>0</enable_wind>
      </link>
      <joint name='front_left_wheel_joint' type='revolute'>
        <pose relative_to='base_link'>0.085 0.153 0.0545 1.5708 -0 -4e-06</pose>
        <parent>base_link</parent>
        <child>front_left_wheel</child>
        <axis>
          <xyz>0 0 -1</xyz>
          <limit>
            <lower>-1e+16</lower>
            <upper>1e+16</upper>
          </limit>
          <dynamics>
            <spring_reference>0</spring_reference>
            <spring_stiffness>0</spring_stiffness>
          </dynamics>
        </axis>
      </joint>
      <link name='front_left_wheel'>
        <pose relative_to='front_left_wheel_joint'>0 0 0 0 -0 0</pose>
        <inertial>
          <pose>0 0 0.025 0 -0 0</pose>
          <mass>2.15</mass>
          <inertia>
            <ixx>0.00188573</ixx>
            <ixy>0</ixy>
            <ixz>0</ixz>
            <iyy>0.00188573</iyy>
            <iyz>0</iyz>
            <izz>0.0026875</izz>
          </inertia>
        </inertial>
        <collision name='front_left_wheel_collision'>
          <pose>0 0 0.025 0 -0 0</pose>
          <geometry>
            <cylinder>
              <length>0.055</length>
              <radius>0.05</radius>
            </cylinder>
          </geometry>
          <max_contacts>10</max_contacts>
          <surface>
            <contact>
              <ode/>
            </contact>
            <bounce/>
            <friction>
              <torsional>
                <ode/>
              </torsional>
              <ode/>
            </friction>
          </surface>
        </collision>
        <visual name='front_left_wheel_visual'>
          <pose>0 0 0 0 -0 0</pose>
          <geometry>
            <mesh>
              <scale>1 1 1</scale>
              <uri>model://mirte_master_description/meshes/wheel_left.STL</uri>
            </mesh>
          </geometry>
        </visual>
        <self_collide>0</self_collide>
        <enable_wind>0</enable_wind>
        <kinematic>0</kinematic>
      </link>
      <joint name='front_right_wheel_joint' type='revolute'>
        <pose relative_to='base_link'>0.085 -0.098 0.0545 1.5708 -0 -4e-06</pose>
        <parent>base_link</parent>
        <child>front_right_wheel</child>
        <axis>
          <xyz>0 0 -1</xyz>
          <limit>
            <lower>-1e+16</lower>
            <upper>1e+16</upper>
          </limit>
          <dynamics>
            <spring_reference>0</spring_reference>
            <spring_stiffness>0</spring_stiffness>
          </dynamics>
        </axis>
      </joint>
      <link name='front_right_wheel'>
        <pose relative_to='front_right_wheel_joint'>0 0 0 0 -0 0</pose>
        <inertial>
          <pose>0 0 -0.025 0 -0 0</pose>
          <mass>2.15</mass>
          <inertia>
            <ixx>0.00188573</ixx>
            <ixy>0</ixy>
            <ixz>0</ixz>
            <iyy>0.00188573</iyy>
            <iyz>0</iyz>
            <izz>0.0026875</izz>
          </inertia>
        </inertial>
        <collision name='front_right_wheel_collision'>
          <pose>0 0 -0.025 0 -0 0</pose>
          <geometry>
            <cylinder>
              <length>0.055</length>
              <radius>0.05</radius>
            </cylinder>
          </geometry>
          <max_contacts>10</max_contacts>
          <surface>
            <contact>
              <ode/>
            </contact>
            <bounce/>
            <friction>
              <torsional>
                <ode/>
              </torsional>
              <ode/>
            </friction>
          </surface>
        </collision>
        <visual name='front_right_wheel_visual'>
          <pose>0 0 0 0 -0 0</pose>
          <geometry>
            <mesh>
              <scale>1 1 1</scale>
              <uri>model://mirte_master_description/meshes/wheel_right.STL</uri>
            </mesh>
          </geometry>
        </visual>
        <self_collide>0</self_collide>
        <enable_wind>0</enable_wind>
        <kinematic>0</kinematic>
      </link>
      <joint name='rear_left_wheel_joint' type='revolute'>
        <pose relative_to='base_link'>-0.085 0.153 0.0545 1.5708 -0 -4e-06</pose>
        <parent>base_link</parent>
        <child>rear_left_wheel</child>
        <axis>
          <xyz>0 0 -1</xyz>
          <limit>
            <lower>-1e+16</lower>
            <upper>1e+16</upper>
          </limit>
          <dynamics>
            <spring_reference>0</spring_reference>
            <spring_stiffness>0</spring_stiffness>
          </dynamics>
        </axis>
      </joint>
      <link name='rear_left_wheel'>
        <pose relative_to='rear_left_wheel_joint'>0 0 0 0 -0 0</pose>
        <inertial>
          <pose>0 0 0.025 0 -0 0</pose>
          <mass>2.15</mass>
          <inertia>
            <ixx>0.00188573</ixx>
            <ixy>0</ixy>
            <ixz>0</ixz>
            <iyy>0.00188573</iyy>
            <iyz>0</iyz>
            <izz>0.0026875</izz>
          </inertia>
        </inertial>
        <collision name='rear_left_wheel_collision'>
          <pose>0 0 0.025 0 -0 0</pose>
          <geometry>
            <cylinder>
              <length>0.055</length>
              <radius>0.05</radius>
            </cylinder>
          </geometry>
          <max_contacts>10</max_contacts>
          <surface>
            <contact>
              <ode/>
            </contact>
            <bounce/>
            <friction>
              <torsional>
                <ode/>
              </torsional>
              <ode/>
            </friction>
          </surface>
        </collision>
        <visual name='rear_left_wheel_visual'>
          <pose>0 0 0 0 -0 0</pose>
          <geometry>
            <mesh>
              <scale>1 1 1</scale>
              <uri>model://mirte_master_description/meshes/wheel_right.STL</uri>
            </mesh>
          </geometry>
        </visual>
        <self_collide>0</self_collide>
        <enable_wind>0</enable_wind>
        <kinematic>0</kinematic>
      </link>
      <joint name='rear_right_wheel_joint' type='revolute'>
        <pose relative_to='base_link'>-0.085 -0.098 0.0545 1.5708 -0 -4e-06</pose>
        <parent>base_link</parent>
        <child>rear_right_wheel</child>
        <axis>
          <xyz>0 0 -1</xyz>
          <limit>
            <lower>-1e+16</lower>
            <upper>1e+16</upper>
          </limit>
          <dynamics>
            <spring_reference>0</spring_reference>
            <spring_stiffness>0</spring_stiffness>
          </dynamics>
        </axis>
      </joint>
      <link name='rear_right_wheel'>
        <pose relative_to='rear_right_wheel_joint'>0 0 0 0 -0 0</pose>
        <inertial>
          <pose>0 0 -0.025 0 -0 0</pose>
          <mass>2.15</mass>
          <inertia>
            <ixx>0.00188573</ixx>
            <ixy>0</ixy>
            <ixz>0</ixz>
            <iyy>0.00188573</iyy>
            <iyz>0</iyz>
            <izz>0.0026875</izz>
          </inertia>
        </inertial>
        <collision name='rear_right_wheel_collision'>
          <pose>0 0 -0.025 0 -0 0</pose>
          <geometry>
            <cylinder>
              <length>0.055</length>
              <radius>0.05</radius>
            </cylinder>
          </geometry>
          <max_contacts>10</max_contacts>
          <surface>
            <contact>
              <ode/>
            </contact>
            <bounce/>
            <friction>
              <torsional>
                <ode/>
              </torsional>
              <ode/>
            </friction>
          </surface>
        </collision>
        <visual name='rear_right_wheel_visual'>
          <pose>0 0 0 0 -0 0</pose>
          <geometry>
            <mesh>
              <scale>1 1 1</scale>
              <uri>model://mirte_master_description/meshes/wheel_left.STL</uri>
            </mesh>
          </geometry>
        </visual>
        <self_collide>0</self_collide>
        <enable_wind>0</enable_wind>
        <kinematic>0</kinematic>
      </link>
      <joint name='shoulder_pan_joint' type='revolute'>
        <pose relative_to='base_link'>0.079274 -0 0.16 1.5708 0 -1.57079</pose>
        <parent>base_link</parent>
        <child>shoulder_pan</child>
        <axis>
          <xyz>0 1 0</xyz>
          <limit>
            <lower>-1.5708</lower>
            <upper>1.5708</upper>
            <effort>2</effort>
            <velocity>2</velocity>
          </limit>
          <dynamics>
            <spring_reference>0</spring_reference>
            <spring_stiffness>0</spring_stiffness>
          </dynamics>
        </axis>
      </joint>
      <link name='shoulder_pan'>
        <pose relative_to='shoulder_pan_joint'>0 0 0 0 -0 0</pose>
        <inertial>
          <pose>-1.3e-05 0.020806 0.005857 0 -0 0</pose>
          <mass>0.0689676</mass>
          <inertia>
            <ixx>1.10737e-05</ixx>
            <ixy>-9.06573e-09</ixy>
            <ixz>-2.13238e-10</ixz>
            <iyy>2.2448e-05</iyy>
            <iyz>-4.10985e-07</iyz>
            <izz>1.70253e-05</izz>
          </inertia>
        </inertial>
        <collision name='shoulder_pan_collision'>
          <pose>0 0 0 0 -0 0</pose>
          <geometry>
            <mesh>
              <scale>1 1 1</scale>
              <uri>model://mirte_master_description/meshes/arm_Rot.STL</uri>
            </mesh>
          </geometry>
          <max_contacts>10</max_contacts>
          <surface>
            <contact>
              <ode/>
            </contact>
            <bounce/>
            <friction>
              <torsional>
                <ode/>
              </torsional>
              <ode/>
            </friction>
          </surface>
        </collision>
        <visual name='shoulder_pan_visual'>
          <pose>0 0 0 0 -0 0</pose>
          <geometry>
            <mesh>
              <scale>1 1 1</scale>
              <uri>model://mirte_master_description/meshes/arm_Rot.STL</uri>
            </mesh>
          </geometry>
        </visual>
        <self_collide>0</self_collide>
        <enable_wind>0</enable_wind>
        <kinematic>0</kinematic>
      </link>
      <joint name='shoulder_lift_joint' type='revolute'>
        <pose relative_to='shoulder_pan'>0 0.0281 -0.00625 -3.14159 -0 1.5708</pose>
        <parent>shoulder_pan</parent>
        <child>shoulder_lift</child>
        <axis>
          <xyz>0 1 0</xyz>
          <limit>
            <lower>-1.5708</lower>
            <upper>1.5708</upper>
            <effort>2</effort>
            <velocity>2</velocity>
          </limit>
          <dynamics>
            <spring_reference>0</spring_reference>
            <spring_stiffness>0</spring_stiffness>
          </dynamics>
        </axis>
      </joint>
      <link name='shoulder_lift'>
        <pose relative_to='shoulder_lift_joint'>0 0 0 0 -0 0</pose>
        <inertial>
          <pose>0.076497 0.000443 -0 0 -0 0</pose>
          <mass>0.104616</mass>
          <inertia>
            <ixx>3.85678e-05</ixx>
            <ixy>1.84827e-08</ixy>
            <ixz>1.42613e-12</ixz>
            <iyy>2.54245e-05</iyy>
            <iyz>-2.05143e-12</iyz>
            <izz>5.51612e-05</izz>
          </inertia>
        </inertial>
        <collision name='shoulder_lift_collision'>
          <pose>0 0 0 0 -0 0</pose>
          <geometry>
            <mesh>
              <scale>1 1 1</scale>
              <uri>model://mirte_master_description/meshes/arm_Shoulder.STL</uri>
            </mesh>
          </geometry>
          <max_contacts>10</max_contacts>
          <surface>
            <contact>
              <ode/>
            </contact>
            <bounce/>
            <friction>
              <torsional>
                <ode/>
              </torsional>
              <ode/>
            </friction>
          </surface>
        </collision>
        <visual name='shoulder_lift_visual'>
          <pose>0 0 0 0 -0 0</pose>
          <geometry>
            <mesh>
              <scale>1 1 1</scale>
              <uri>model://mirte_master_description/meshes/arm_Shoulder.STL</uri>
            </mesh>
          </geometry>
        </visual>
        <self_collide>0</self_collide>
        <enable_wind>0</enable_wind>
        <kinematic>0</kinematic>
      </link>
      <joint name='elbow_joint' type='revolute'>
        <pose relative_to='shoulder_lift'>0.1378 0 0 3.14159 -0 1.5708</pose>
        <parent>shoulder_lift</parent>
        <child>elbow</child>
        <axis>
          <xyz>1 0 0</xyz>
          <limit>
            <lower>-1.5708</lower>
            <upper>1.5708</upper>
            <effort>2</effort>
            <velocity>2</velocity>
          </limit>
          <dynamics>
            <spring_reference>0</spring_reference>
            <spring_stiffness>0</spring_stiffness>
          </dynamics>
        </axis>
      </joint>
      <link name='elbow'>
        <pose relative_to='elbow_joint'>0 0 0 0 -0 0</pose>
        <inertial>
          <pose>0.000769 0.064229 -0 0 -0 0</pose>
          <mass>0.0709796</mass>
          <inertia>
            <ixx>2.06492e-05</ixx>
            <ixy>1.76078e-08</ixy>
            <ixz>-6.063e-13</ixz>
            <iyy>2.45687e-05</iyy>
            <iyz>3.04034e-12</iyz>
            <izz>3.79131e-05</izz>
          </inertia>
        </inertial>
        <collision name='elbow_collision'>
          <pose>0 0 0 0 -0 0</pose>
          <geometry>
            <mesh>
              <scale>1 1 1</scale>
              <uri>model://mirte_master_description/meshes/arm_Elbow.STL</uri>
            </mesh>
          </geometry>
          <max_contacts>10</max_contacts>
          <surface>
            <contact>
              <ode/>
            </contact>
            <bounce/>
            <friction>
              <torsional>
                <ode/>
              </torsional>
              <ode/>
            </friction>
          </surface>
        </collision>
        <visual name='elbow_visual'>
          <pose>0 0 0 0 -0 0</pose>
          <geometry>
            <mesh>
              <scale>1 1 1</scale>
              <uri>model://mirte_master_description/meshes/arm_Elbow.STL</uri>
            </mesh>
          </geometry>
        </visual>
        <self_collide>0</self_collide>
        <enable_wind>0</enable_wind>
        <kinematic>0</kinematic>
      </link>
      <joint name='wrist_joint' type='revolute'>
        <pose relative_to='elbow'>-0.00014 0.14265 0 -3.14159 -0 1.5708</pose>
        <parent>elbow</parent>
        <child>wrist</child>
        <axis>
          <xyz>0 1 0</xyz>
          <limit>
            <lower>-1.5708</lower>
            <upper>1.5708</upper>
            <effort>2</effort>
            <velocity>2</velocity>
          </limit>
          <dynamics>
            <spring_reference>0</spring_reference>
            <spring_stiffness>0</spring_stiffness>
          </dynamics>
        </axis>
      </joint>
      <link name='wrist'>
        <pose relative_to='wrist_joint'>0 0 0 0 -0 0</pose>
        <inertial>
          <pose>0.022532 0.000488 -3e-06 0 -0 0</pose>
          <mass>0.0464804</mass>
          <inertia>
            <ixx>1.36228e-05</ixx>
            <ixy>-2.74862e-08</ixy>
            <ixz>-2.8218e-08</ixz>
            <iyy>7.22412e-06</iyy>
            <iyz>3.46527e-09</iyz>
            <izz>1.75204e-05</izz>
          </inertia>
        </inertial>
        <collision name='wrist_collision'>
          <pose>0 0 0 0 -0 0</pose>
          <geometry>
            <mesh>
              <scale>1 1 1</scale>
              <uri>model://mirte_master_description/meshes/arm_Wrist.STL</uri>
            </mesh>
          </geometry>
          <max_contacts>10</max_contacts>
          <surface>
            <contact>
              <ode/>
            </contact>
            <bounce/>
            <friction>
              <torsional>
                <ode/>
              </torsional>
              <ode/>
            </friction>
          </surface>
        </collision>
        <visual name='wrist_visual'>
          <pose>0 0 0 0 -0 0</pose>
          <geometry>
            <mesh>
              <scale>1 1 1</scale>
              <uri>model://mirte_master_description/meshes/arm_Wrist.STL</uri>
            </mesh>
          </geometry>
        </visual>
        <self_collide>0</self_collide>
        <enable_wind>0</enable_wind>
        <kinematic>0</kinematic>
      </link>
      <joint name='_Gripper_joint_r' type='revolute'>
        <pose relative_to='wrist'>0.0435 0.012 0.0045 -1.5708 -0 3.14159</pose>
        <parent>wrist</parent>
        <child>_Gripper_r</child>
        <axis>
          <xyz>0 -1 0</xyz>
          <limit>
            <lower>-0.25</lower>
            <upper>0.2</upper>
            <effort>2</effort>
            <velocity>2</velocity>
          </limit>
          <dynamics>
            <spring_reference>0</spring_reference>
            <spring_stiffness>0</spring_stiffness>
          </dynamics>
        </axis>
      </joint>
      <link name='_Gripper_r'>
        <pose relative_to='_Gripper_joint_r'>0 0 0 0 -0 0</pose>
        <inertial>
          <pose>-0.011059 0.005724 -0.020303 0 -0 0</pose>
          <mass>0.0127577</mass>
          <inertia>
            <ixx>1.91784e-06</ixx>
            <ixy>-2.13317e-10</ixy>
            <ixz>3.18098e-07</ixz>
            <iyy>3.19295e-06</iyy>
            <iyz>-1.86219e-07</iyz>
            <izz>1.63755e-06</izz>
          </inertia>
        </inertial>
        <collision name='_Gripper_r_collision'>
          <pose>0 0 0 0 -0 0</pose>
          <geometry>
            <mesh>
              <scale>1 1 1</scale>
              <uri>model://mirte_master_description/meshes/_Gripper_r.STL</uri>
            </mesh>
          </geometry>
          <max_contacts>10</max_contacts>
          <surface>
            <contact>
              <ode/>
            </contact>
            <bounce/>
            <friction>
              <torsional>
                <ode/>
              </torsional>
              <ode/>
            </friction>
          </surface>
        </collision>
        <visual name='_Gripper_r_visual'>
          <pose>0 0 0 0 -0 0</pose>
          <geometry>
            <mesh>
              <scale>1 1 1</scale>
              <uri>model://mirte_master_description/meshes/_Gripper_r.STL</uri>
            </mesh>
          </geometry>
        </visual>
        <self_collide>0</self_collide>
        <enable_wind>0</enable_wind>
        <kinematic>0</kinematic>
      </link>
      <joint name='_gripper_link_joint_l' type='revolute'>
        <pose relative_to='wrist'>0.0605 -0.0205 -0.0055 1.5708 -0 -1.7775</pose>
        <parent>wrist</parent>
        <child>_gripper_link_l</child>
        <axis>
          <xyz>0 -1 0</xyz>
          <limit>
            <lower>-3.14</lower>
            <upper>3.14</upper>
            <effort>0</effort>
            <velocity>0</velocity>
          </limit>
          <dynamics>
            <spring_reference>0</spring_reference>
            <spring_stiffness>0</spring_stiffness>
          </dynamics>
        </axis>
      </joint>
      <link name='_gripper_link_l'>
        <pose relative_to='_gripper_link_joint_l'>0 0 0 0 -0 0</pose>
        <inertial>
          <pose>0.001504 0.004727 -0.040419 0 -0 0</pose>
          <mass>0.00789063</mass>
          <inertia>
            <ixx>3.42723e-06</ixx>
            <ixy>-2.00727e-08</ixy>
            <ixz>-6.25732e-08</ixz>
            <iyy>3.61547e-06</iyy>
            <iyz>7.56101e-08</iyz>
            <izz>3.17661e-07</izz>
          </inertia>
        </inertial>
        <collision name='_gripper_link_l_collision'>
          <pose>0 0 0 0 -0 0</pose>
          <geometry>
            <mesh>
              <scale>1 1 1</scale>
              <uri>model://mirte_master_description/meshes/_gripper_link_l.STL</uri>
            </mesh>
          </geometry>
          <max_contacts>10</max_contacts>
          <surface>
            <contact>
              <ode/>
            </contact>
            <bounce/>
            <friction>
              <torsional>
                <ode/>
              </torsional>
              <ode/>
            </friction>
          </surface>
        </collision>
        <collision name='_gripper_link_l_fixed_joint_lump__gripper_finger_l_collision_1'>
          <pose>0 0 -0.037 0 0.20667 0</pose>
          <geometry>
            <mesh>
              <scale>1 1 1</scale>
              <uri>model://mirte_master_description/meshes/gripper_finger_l.STL</uri>
            </mesh>
          </geometry>
          <max_contacts>10</max_contacts>
          <surface>
            <contact>
              <ode/>
            </contact>
            <bounce/>
            <friction>
              <torsional>
                <ode/>
              </torsional>
              <ode/>
            </friction>
          </surface>
        </collision>
        <visual name='_gripper_link_l_visual'>
          <pose>0 0 0 0 -0 0</pose>
          <geometry>
            <mesh>
              <scale>1 1 1</scale>
              <uri>model://mirte_master_description/meshes/_gripper_link_l.STL</uri>
            </mesh>
          </geometry>
        </visual>
        <visual name='_gripper_link_l_fixed_joint_lump__gripper_finger_l_visual_1'>
          <pose>0 0 -0.037 0 0.20667 0</pose>
          <geometry>
            <mesh>
              <scale>1 1 1</scale>
              <uri>model://mirte_master_description/meshes/gripper_finger_l.STL</uri>
            </mesh>
          </geometry>
        </visual>
        <self_collide>0</self_collide>
        <enable_wind>0</enable_wind>
        <kinematic>0</kinematic>
      </link>
      <joint name='_gripper_link_joint_r' type='revolute'>
        <pose relative_to='wrist'>0.0605 0.0205 -0.0055 1.5708 -0 -1.3641</pose>
        <parent>wrist</parent>
        <child>_gripper_link_r</child>
        <axis>
          <xyz>0 -1 0</xyz>
          <limit>
            <lower>-3.14</lower>
            <upper>3.14</upper>
            <effort>0</effort>
            <velocity>0</velocity>
          </limit>
          <dynamics>
            <spring_reference>0</spring_reference>
            <spring_stiffness>0</spring_stiffness>
          </dynamics>
        </axis>
      </joint>
      <link name='_gripper_link_r'>
        <pose relative_to='_gripper_link_joint_r'>0 0 0 0 -0 0</pose>
        <inertial>
          <pose>-0.001504 0.004727 -0.04042 0 -0 0</pose>
          <mass>0.00789063</mass>
          <inertia>
            <ixx>3.42723e-06</ixx>
            <ixy>2.0071e-08</ixy>
            <ixz>6.25763e-08</ixz>
            <iyy>3.61546e-06</iyy>
            <iyz>7.56091e-08</iyz>
            <izz>3.1766e-07</izz>
          </inertia>
        </inertial>
        <collision name='_gripper_link_r_collision'>
          <pose>0 0 0 0 -0 0</pose>
          <geometry>
            <mesh>
              <scale>1 1 1</scale>
              <uri>model://mirte_master_description/meshes/_gripper_link_r.STL</uri>
            </mesh>
          </geometry>
          <max_contacts>10</max_contacts>
          <surface>
            <contact>
              <ode/>
            </contact>
            <bounce/>
            <friction>
              <torsional>
                <ode/>
              </torsional>
              <ode/>
            </friction>
          </surface>
        </collision>
        <collision name='_gripper_link_r_fixed_joint_lump__gripper_finger_r_collision_1'>
          <pose>0 0.01 -0.037 0 0.20667 -3.14159</pose>
          <geometry>
            <mesh>
              <scale>1 1 1</scale>
              <uri>model://mirte_master_description/meshes/gripper_finger_r.STL</uri>
            </mesh>
          </geometry>
          <max_contacts>10</max_contacts>
          <surface>
            <contact>
              <ode/>
            </contact>
            <bounce/>
            <friction>
              <torsional>
                <ode/>
              </torsional>
              <ode/>
            </friction>
          </surface>
        </collision>
        <visual name='_gripper_link_r_visual'>
          <pose>0 0 0 0 -0 0</pose>
          <geometry>
            <mesh>
              <scale>1 1 1</scale>
              <uri>model://mirte_master_description/meshes/_gripper_link_r.STL</uri>
            </mesh>
          </geometry>
        </visual>
        <visual name='_gripper_link_r_fixed_joint_lump__gripper_finger_r_visual_1'>
          <pose>0 0.01 -0.037 0 0.20667 -3.14159</pose>
          <geometry>
            <mesh>
              <scale>1 1 1</scale>
              <uri>model://mirte_master_description/meshes/gripper_finger_r.STL</uri>
            </mesh>
          </geometry>
        </visual>
        <self_collide>0</self_collide>
        <enable_wind>0</enable_wind>
        <kinematic>0</kinematic>
      </link>
      <joint name='gripper_joint' type='revolute'>
        <pose relative_to='wrist'>0.0435 -0.012 0.0045 -1.5708 0 0</pose>
        <parent>wrist</parent>
        <child>gripper</child>
        <axis>
          <xyz>0 -1 0</xyz>
          <limit>
            <lower>-0.2</lower>
            <upper>0.25</upper>
            <effort>2</effort>
            <velocity>2</velocity>
          </limit>
          <dynamics>
            <spring_reference>0</spring_reference>
            <spring_stiffness>0</spring_stiffness>
          </dynamics>
        </axis>
      </joint>
      <link name='gripper'>
        <pose relative_to='gripper_joint'>0 0 0 0 -0 0</pose>
        <inertial>
          <pose>0.012844 0.004671 -0.023532 0 -0 0</pose>
          <mass>0.0109604</mass>
          <inertia>
            <ixx>1.64287e-06</ixx>
            <ixy>-2.54916e-10</ixy>
            <ixz>-3.17766e-07</ixz>
            <iyy>2.9664e-06</iyy>
            <iyz>-7.8877e-08</iyz>
            <izz>1.49194e-06</izz>
          </inertia>
        </inertial>
        <collision name='gripper_collision'>
          <pose>0 0 0 0 -0 0</pose>
          <geometry>
            <mesh>
              <scale>1 1 1</scale>
              <uri>model://mirte_master_description/meshes/Gripper.STL</uri>
            </mesh>
          </geometry>
          <max_contacts>10</max_contacts>
          <surface>
            <contact>
              <ode/>
            </contact>
            <bounce/>
            <friction>
              <torsional>
                <ode/>
              </torsional>
              <ode/>
            </friction>
          </surface>
        </collision>
        <visual name='gripper_visual'>
          <pose>0 0 0 0 -0 0</pose>
          <geometry>
            <mesh>
              <scale>1 1 1</scale>
              <uri>model://mirte_master_description/meshes/Gripper.STL</uri>
            </mesh>
          </geometry>
        </visual>
        <self_collide>0</self_collide>
        <enable_wind>0</enable_wind>
        <kinematic>0</kinematic>
      </link>
      <plugin name='gazebo_ros2_control' filename='libgazebo_ros2_control.so'>
        <parameters>/home/fn8211/MDP/install/mirte_base_control/share/mirte_base_control/config/mirte_base_control.yaml</parameters>
        <parameters>/home/fn8211/MDP/install/mirte_master_arm_control/share/mirte_master_arm_control/config/mirte_master_arm_control.yaml</parameters>
      </plugin>
      <plugin name='gazebo_planar_move' filename='libgazebo_ros_planar_move.so'>
        <robot_base_frame>base_link</robot_base_frame>
      </plugin>
      <plugin name='libgazebo_ros_p3d' filename='libgazebo_ros_p3d.so'>
        <ros>
          <namespace>groundtruth</namespace>
          <remapping>odom:=odom</remapping>
        </ros>
        <frame_name>world</frame_name>
        <body_name>base_link</body_name>
        <update_rate>200.0</update_rate>
        <gaussian_noise>0.0</gaussian_noise>
      </plugin>
      <static>0</static>
      <plugin name='gazebo_grasp_fix' filename='libgazebo_grasp_fix.so'>
        <arm>
          <arm_name>finger_gripper</arm_name>
          <palm_link>wrist</palm_link>
          <gripper_link>gripper</gripper_link>
          <gripper_link>_Gripper_r</gripper_link>
          <gripper_link>_gripper_link_l</gripper_link>
          <gripper_link>gripper_finger_l</gripper_link>
          <gripper_link>_gripper_link_r</gripper_link>
          <gripper_link>gripper_finger_r</gripper_link>
        </arm>
        <forces_angle_tolerance>100</forces_angle_tolerance>
        <update_rate>4</update_rate>
        <grip_count_threshold>4</grip_count_threshold>
        <max_grip_count>8</max_grip_count>
        <release_tolerance>0.005</release_tolerance>
        <disable_collisions_on_attach>0</disable_collisions_on_attach>
      </plugin>
      <pose>1.0527 0.509611 0.021444 0 -0 0</pose>
    </model>
    <state world_name='mdp_greenhouse'>
      <sim_time>628 534000000</sim_time>
      <real_time>372 65319384</real_time>
      <wall_time>1778779606 677280331</wall_time>
      <iterations>370524</iterations>
      <model name='apriltag_1'>
        <pose>0.798845 7.34697 -0 0 -0 0</pose>
        <scale>1 1 1</scale>
        <link name='link'>
          <pose>0.798845 7.34697 0.17 3.14159 1.57079 3.14159</pose>
          <velocity>0 0 0 0 -0 0</velocity>
          <acceleration>0 0 0 0 -0 0</acceleration>
          <wrench>0 0 0 0 -0 0</wrench>
        </link>
      </model>
      <model name='apriltag_10'>
        <pose>3.47387 3.15119 -0 0 -0 0</pose>
        <scale>1 1 1</scale>
        <link name='link'>
          <pose>3.47387 3.15119 0.17 1.5708 -0 0</pose>
          <velocity>0 0 0 0 -0 0</velocity>
          <acceleration>0 0 0 0 -0 0</acceleration>
          <wrench>0 0 0 0 -0 0</wrench>
        </link>
      </model>
      <model name='apriltag_11'>
        <pose>1.21358 2.1504 -0 0 -0 0</pose>
        <scale>1 1 1</scale>
        <link name='link'>
          <pose>1.21358 2.1504 0.17 1.5708 -0 0</pose>
          <velocity>0 0 0 0 -0 0</velocity>
          <acceleration>0 0 0 0 -0 0</acceleration>
          <wrench>0 0 0 0 -0 0</wrench>
        </link>
      </model>
      <model name='apriltag_12'>
        <pose>3.64443 2.15148 -0 0 -0 0</pose>
        <scale>1 1 1</scale>
        <link name='link'>
          <pose>3.64443 2.15148 0.17 1.5708 -0 0</pose>
          <velocity>0 0 0 0 -0 0</velocity>
          <acceleration>0 0 0 0 -0 0</acceleration>
          <wrench>0 0 0 0 -0 0</wrench>
        </link>
      </model>
      <model name='apriltag_2'>
        <pose>2.19933 7.28987 -0 0 -0 0</pose>
        <scale>1 1 1</scale>
        <link name='link'>
          <pose>2.19933 7.28987 0.17 3.14159 1.57079 3.14159</pose>
          <velocity>0 0 0 0 -0 0</velocity>
          <acceleration>0 0 0 0 -0 0</acceleration>
          <wrench>0 0 0 0 -0 0</wrench>
        </link>
      </model>
      <model name='apriltag_3'>
        <pose>3.39983 7.10297 -0 0 -0 0</pose>
        <scale>1 1 1</scale>
        <link name='link'>
          <pose>3.39983 7.10297 0.17 3.14159 1.57079 3.14159</pose>
          <velocity>0 0 0 0 -0 0</velocity>
          <acceleration>0 0 0 0 -0 0</acceleration>
          <wrench>0 0 0 0 -0 0</wrench>
        </link>
      </model>
      <model name='apriltag_4'>
        <pose>0.798891 5.51092 -0 0 -0 0</pose>
        <scale>1 1 1</scale>
        <link name='link'>
          <pose>0.798891 5.51092 0.17 3.14159 1.57079 3.14159</pose>
          <velocity>0 0 0 0 -0 0</velocity>
          <acceleration>0 0 0 0 -0 0</acceleration>
          <wrench>0 0 0 0 -0 0</wrench>
        </link>
      </model>
      <model name='apriltag_5'>
        <pose>2.19787 5.68217 -0 0 -0 0</pose>
        <scale>1 1 1</scale>
        <link name='link'>
          <pose>2.19787 5.68217 0.17 3.14159 1.57079 3.14159</pose>
          <velocity>0 0 0 0 -0 0</velocity>
          <acceleration>0 0 0 0 -0 0</acceleration>
          <wrench>0 0 0 0 -0 0</wrench>
        </link>
      </model>
      <model name='apriltag_6'>
        <pose>3.39879 5.41894 -0 0 -0 0</pose>
        <scale>1 1 1</scale>
        <link name='link'>
          <pose>3.39879 5.41894 0.17 3.14159 1.57079 3.14159</pose>
          <velocity>0 0 0 0 -0 0</velocity>
          <acceleration>0 0 0 0 -0 0</acceleration>
          <wrench>0 0 0 0 -0 0</wrench>
        </link>
      </model>
      <model name='apriltag_7'>
        <pose>1.40567 4.15006 -0 0 -0 0</pose>
        <scale>1 1 1</scale>
        <link name='link'>
          <pose>1.40567 4.15006 0.17 1.5708 -0 0</pose>
          <velocity>0 0 0 0 -0 0</velocity>
          <acceleration>0 0 0 0 -0 0</acceleration>
          <wrench>0 0 0 0 -0 0</wrench>
        </link>
      </model>
      <model name='apriltag_8'>
        <pose>3.61425 4.15086 -0 0 -0 0</pose>
        <scale>1 1 1</scale>
        <link name='link'>
          <pose>3.61425 4.15086 0.17 1.5708 -0 0</pose>
          <velocity>0 0 0 0 -0 0</velocity>
          <acceleration>0 0 0 0 -0 0</acceleration>
          <wrench>0 0 0 0 -0 0</wrench>
        </link>
      </model>
      <model name='apriltag_9'>
        <pose>1.30993 3.15197 -0 0 -0 0</pose>
        <scale>1 1 1</scale>
        <link name='link'>
          <pose>1.30993 3.15197 0.17 1.5708 -0 0</pose>
          <velocity>0 0 0 0 -0 0</velocity>
          <acceleration>0 0 0 0 -0 0</acceleration>
          <wrench>0 0 0 0 -0 0</wrench>
        </link>
      </model>
      <model name='mdp_greenhouse_environment'>
        <pose>0 0 0 0 -0 0</pose>
        <scale>1 1 1</scale>
        <link name='east_wall'>
          <pose>5.04 5 0.75 0 -0 0</pose>
          <velocity>0 0 0 0 -0 0</velocity>
          <acceleration>0 0 0 0 -0 0</acceleration>
          <wrench>0 0 0 0 -0 0</wrench>
        </link>
        <link name='floor'>
          <pose>2.5 5 -0.01 0 -0 0</pose>
          <velocity>0 0 0 0 -0 0</velocity>
          <acceleration>0 0 0 0 -0 0</acceleration>
          <wrench>0 0 0 0 -0 0</wrench>
        </link>
        <link name='north_wall'>
          <pose>2.5 10.04 0.75 0 -0 0</pose>
          <velocity>0 0 0 0 -0 0</velocity>
          <acceleration>0 0 0 0 -0 0</acceleration>
          <wrench>0 0 0 0 -0 0</wrench>
        </link>
        <link name='south_wall'>
          <pose>2.5 -0.04 0.75 0 -0 0</pose>
          <velocity>0 0 0 0 -0 0</velocity>
          <acceleration>0 0 0 0 -0 0</acceleration>
          <wrench>0 0 0 0 -0 0</wrench>
        </link>
        <link name='table_1'>
          <pose>1.25 2.025 0.1 0 -0 0</pose>
          <velocity>0 0 0 0 -0 0</velocity>
          <acceleration>0 0 0 0 -0 0</acceleration>
          <wrench>0 0 0 0 -0 0</wrench>
        </link>
        <link name='table_10'>
          <pose>0.925 7.25 0.1 0 -0 0</pose>
          <velocity>0 0 0 0 -0 0</velocity>
          <acceleration>0 0 0 0 -0 0</acceleration>
          <wrench>0 0 0 0 -0 0</wrench>
        </link>
        <link name='table_11'>
          <pose>2.325 7.25 0.1 0 -0 0</pose>
          <velocity>0 0 0 0 -0 0</velocity>
          <acceleration>0 0 0 0 -0 0</acceleration>
          <wrench>0 0 0 0 -0 0</wrench>
        </link>
        <link name='table_12'>
          <pose>3.525 7.25 0.1 0 -0 0</pose>
          <velocity>0 0 0 0 -0 0</velocity>
          <acceleration>0 0 0 0 -0 0</acceleration>
          <wrench>0 0 0 0 -0 0</wrench>
        </link>
        <link name='table_2'>
          <pose>3.55 2.025 0.1 0 -0 0</pose>
          <velocity>0 0 0 0 -0 0</velocity>
          <acceleration>0 0 0 0 -0 0</acceleration>
          <wrench>0 0 0 0 -0 0</wrench>
        </link>
        <link name='table_3'>
          <pose>1.25 3.025 0.1 0 -0 0</pose>
          <velocity>0 0 0 0 -0 0</velocity>
          <acceleration>0 0 0 0 -0 0</acceleration>
          <wrench>0 0 0 0 -0 0</wrench>
        </link>
        <link name='table_4'>
          <pose>3.55 3.025 0.1 0 -0 0</pose>
          <velocity>0 0 0 0 -0 0</velocity>
          <acceleration>0 0 0 0 -0 0</acceleration>
          <wrench>0 0 0 0 -0 0</wrench>
        </link>
        <link name='table_5'>
          <pose>1.35 4.025 0.1 0 -0 0</pose>
          <velocity>0 0 0 0 -0 0</velocity>
          <acceleration>0 0 0 0 -0 0</acceleration>
          <wrench>0 0 0 0 -0 0</wrench>
        </link>
        <link name='table_6'>
          <pose>3.55 4.025 0.1 0 -0 0</pose>
          <velocity>0 0 0 0 -0 0</velocity>
          <acceleration>0 0 0 0 -0 0</acceleration>
          <wrench>0 0 0 0 -0 0</wrench>
        </link>
        <link name='table_7'>
          <pose>0.925 5.55 0.1 0 -0 0</pose>
          <velocity>0 0 0 0 -0 0</velocity>
          <acceleration>0 0 0 0 -0 0</acceleration>
          <wrench>0 0 0 0 -0 0</wrench>
        </link>
        <link name='table_8'>
          <pose>2.325 5.55 0.1 0 -0 0</pose>
          <velocity>0 0 0 0 -0 0</velocity>
          <acceleration>0 0 0 0 -0 0</acceleration>
          <wrench>0 0 0 0 -0 0</wrench>
        </link>
        <link name='table_9'>
          <pose>3.525 5.55 0.1 0 -0 0</pose>
          <velocity>0 0 0 0 -0 0</velocity>
          <acceleration>0 0 0 0 -0 0</acceleration>
          <wrench>0 0 0 0 -0 0</wrench>
        </link>
        <link name='west_wall'>
          <pose>-0.04 5 0.75 0 -0 0</pose>
          <velocity>0 0 0 0 -0 0</velocity>
          <acceleration>0 0 0 0 -0 0</acceleration>
          <wrench>0 0 0 0 -0 0</wrench>
        </link>
      </model>
      <model name='mirte'>
        <pose>1.0527 0.509611 0.021444 0 -0 0</pose>
        <scale>1 1 1</scale>
        <link name='_Gripper_r'>
          <pose>1.32166 0.497712 0.055924 1.56842 -0.151198 -3.12607</pose>
          <velocity>-0.000327 -0 -0.009 0.001073 0.028903 0.007623</velocity>
          <acceleration>-0.059491 0.087963 -9.37102 2.59079 1.02457 1.02238</acceleration>
          <wrench>-0.000759 0.001122 -0.119553 0 -0 0</wrench>
        </link>
        <link name='_gripper_link_l'>
          <pose>1.33998 0.530208 0.063249 -1.42212 -0.027701 1.75347</pose>
          <velocity>-0.00011 0 -0.009505 -0.000865 0.028969 -0.001119</velocity>
          <acceleration>-0.407303 -0.051745 -10.6215 -0.9945 -0.798977 -0.016875</acceleration>
          <wrench>-0.003214 -0.000408 -0.083811 0 -0 0</wrench>
        </link>
        <link name='_gripper_link_r'>
          <pose>1.33997 0.489208 0.063249 -1.42211 0.027703 1.38771</pose>
          <velocity>-0.00011 3e-06 -0.009538 0.000556 0.029959 0.00114</velocity>
          <acceleration>-0.41832 0.052531 -10.6905 0.539711 1.41116 2.42516</acceleration>
          <wrench>-0.003301 0.000415 -0.084355 0 -0 0</wrench>
        </link>
        <link name='base_link'>
          <pose>1.0527 0.509611 0.021444 0 -0 0</pose>
          <velocity>0 0 0 0 -0 0</velocity>
          <acceleration>0 0 -1.73093 0 -0 0</acceleration>
          <wrench>0 0 -9.8066 0 -0 0</wrench>
        </link>
        <link name='elbow'>
          <pose>1.27603 0.509582 0.209537 -1.54759 -3e-06 -1.571</pose>
          <velocity>0.000613 -7e-06 -0.007675 6.1e-05 0.004327 -3.3e-05</velocity>
          <acceleration>0.335145 -0.002798 -7.68173 0.036224 -1.13522 -0.055665</acceleration>
          <wrench>0.023788 -0.000199 -0.545246 0 -0 0</wrench>
        </link>
        <link name='front_left_wheel'>
          <pose>1.1377 0.662611 0.075944 1.5708 -0 -4e-06</pose>
          <velocity>0 0 0 0 -0 0</velocity>
          <acceleration>-0 0 -0 0 -0 0</acceleration>
          <wrench>-0 0 -0 0 -0 0</wrench>
        </link>
        <link name='front_right_wheel'>
          <pose>1.1377 0.411611 0.075944 1.5708 -0 -4e-06</pose>
          <velocity>0 -0 0 -0 -0 -0</velocity>
          <acceleration>0 0 -0 0 -0 0</acceleration>
          <wrench>0 0 -0 0 -0 0</wrench>
        </link>
        <link name='gripper'>
          <pose>1.32167 0.521712 0.055924 1.56842 0.151208 -0.015934</pose>
          <velocity>-0.00034 2e-06 -0.009042 -0.001008 0.030636 -0.007451</velocity>
          <acceleration>-0.085946 -0.097732 -9.48678 1.13773 1.47367 1.88196</acceleration>
          <wrench>-0.000942 -0.001071 -0.103979 0 -0 0</wrench>
        </link>
        <link name='rear_left_wheel'>
          <pose>0.9677 0.662611 0.075944 1.5708 -0 -4e-06</pose>
          <velocity>-0 0 -0 -0 -0 -0</velocity>
          <acceleration>-0 0 0 0 -0 0</acceleration>
          <wrench>-0 0 0 0 -0 0</wrench>
        </link>
        <link name='rear_right_wheel'>
          <pose>0.9677 0.411611 0.075944 1.5708 -0 -4e-06</pose>
          <velocity>-0 -0 0 0 -0 0</velocity>
          <acceleration>-0 -0 0 0 -0 0</acceleration>
          <wrench>-0 -0 0 0 -0 0</wrench>
        </link>
        <link name='shoulder_lift'>
          <pose>1.13823 0.50961 0.209539 3.14159 1e-06 -0.000202</pose>
          <velocity>0.000603 -2e-06 -0.000779 6.7e-05 0.048091 -3.3e-05</velocity>
          <acceleration>0.603115 -0.004832 -4.45758 -3.02541 -0.967673 3.10835</acceleration>
          <wrench>0.063095 -0.000505 -0.466334 0 -0 0</wrench>
        </link>
        <link name='shoulder_pan'>
          <pose>1.13198 0.509611 0.181446 1.57086 -0 -1.571</pose>
          <velocity>0.00085 -3e-06 0.000245 -3.5e-05 -0.009114 -2.8e-05</velocity>
          <acceleration>0.660485 -0.002239 0.191728 -0.023001 0.374683 0.153372</acceleration>
          <wrench>0.045552 -0.000154 0.013223 0 -0 0</wrench>
        </link>
        <link name='wrist'>
          <pose>1.27934 0.509721 0.066926 -3.14159 0.151229 -0.000208</pose>
          <velocity>0 2e-06 -0.007705 5.6e-05 0.030981 -3.4e-05</velocity>
          <acceleration>-0.104739 0.00153 -8.39475 -0.064388 -0.434949 -0.024585</acceleration>
          <wrench>-0.004868 7.1e-05 -0.390192 0 -0 0</wrench>
        </link>
      </model>
      <light name='sun'>
        <pose>2.5 5 10 0 -0 0</pose>
      </light>
    </state>
    <gui fullscreen='0'>
      <camera name='user_camera'>
        <pose>3.40044 3.26227 1.83787 0 0.973798 -1.75497</pose>
        <view_controller>orbit</view_controller>
        <projection_type>perspective</projection_type>
      </camera>
    </gui>
    <model name='apriltag_1'>
      <static>1</static>
      <link name='link'>
        <pose>0 0 0.17 3.14159 1.57079 3.14159</pose>
        <visual name='visual'>
          <geometry>
            <box>
              <size>0.04 0.04 0.001</size>
            </box>
          </geometry>
          <material>
            <script>
              <uri>model://apriltag_1/materials/scripts</uri>
              <uri>model://apriltag_1/materials/textures</uri>
              <name>AprilTag/Tag1</name>
            </script>
          </material>
        </visual>
        <collision name='collision'>
          <geometry>
            <box>
              <size>0.04 0.04 0.001</size>
            </box>
          </geometry>
          <max_contacts>10</max_contacts>
          <surface>
            <contact>
              <ode/>
            </contact>
            <bounce/>
            <friction>
              <torsional>
                <ode/>
              </torsional>
              <ode/>
            </friction>
          </surface>
        </collision>
        <self_collide>0</self_collide>
        <enable_wind>0</enable_wind>
        <kinematic>0</kinematic>
      </link>
      <pose>0.798845 7.34697 0 0 -0 0</pose>
    </model>
    <model name='apriltag_2'>
      <static>1</static>
      <link name='link'>
        <pose>0 0 0.17 3.14159 1.57079 3.14159</pose>
        <visual name='visual'>
          <geometry>
            <box>
              <size>0.04 0.04 0.001</size>
            </box>
          </geometry>
          <material>
            <script>
              <uri>model://apriltag_2/materials/scripts</uri>
              <uri>model://apriltag_2/materials/textures</uri>
              <name>AprilTag/Tag2</name>
            </script>
          </material>
        </visual>
        <collision name='collision'>
          <geometry>
            <box>
              <size>0.04 0.04 0.001</size>
            </box>
          </geometry>
          <max_contacts>10</max_contacts>
          <surface>
            <contact>
              <ode/>
            </contact>
            <bounce/>
            <friction>
              <torsional>
                <ode/>
              </torsional>
              <ode/>
            </friction>
          </surface>
        </collision>
        <self_collide>0</self_collide>
        <enable_wind>0</enable_wind>
        <kinematic>0</kinematic>
      </link>
      <pose>2.19933 7.28987 0 0 -0 0</pose>
    </model>
    <model name='apriltag_3'>
      <static>1</static>
      <link name='link'>
        <pose>0 0 0.17 3.14159 1.57079 3.14159</pose>
        <visual name='visual'>
          <geometry>
            <box>
              <size>0.04 0.04 0.001</size>
            </box>
          </geometry>
          <material>
            <script>
              <uri>model://apriltag_3/materials/scripts</uri>
              <uri>model://apriltag_3/materials/textures</uri>
              <name>AprilTag/Tag3</name>
            </script>
          </material>
        </visual>
        <collision name='collision'>
          <geometry>
            <box>
              <size>0.04 0.04 0.001</size>
            </box>
          </geometry>
          <max_contacts>10</max_contacts>
          <surface>
            <contact>
              <ode/>
            </contact>
            <bounce/>
            <friction>
              <torsional>
                <ode/>
              </torsional>
              <ode/>
            </friction>
          </surface>
        </collision>
        <self_collide>0</self_collide>
        <enable_wind>0</enable_wind>
        <kinematic>0</kinematic>
      </link>
      <pose>3.39983 7.10297 0 0 -0 0</pose>
    </model>
    <model name='apriltag_4'>
      <static>1</static>
      <link name='link'>
        <pose>0 0 0.17 3.14159 1.57079 3.14159</pose>
        <visual name='visual'>
          <geometry>
            <box>
              <size>0.04 0.04 0.001</size>
            </box>
          </geometry>
          <material>
            <script>
              <uri>model://apriltag_4/materials/scripts</uri>
              <uri>model://apriltag_4/materials/textures</uri>
              <name>AprilTag/Tag4</name>
            </script>
          </material>
        </visual>
        <collision name='collision'>
          <geometry>
            <box>
              <size>0.04 0.04 0.001</size>
            </box>
          </geometry>
          <max_contacts>10</max_contacts>
          <surface>
            <contact>
              <ode/>
            </contact>
            <bounce/>
            <friction>
              <torsional>
                <ode/>
              </torsional>
              <ode/>
            </friction>
          </surface>
        </collision>
        <self_collide>0</self_collide>
        <enable_wind>0</enable_wind>
        <kinematic>0</kinematic>
      </link>
      <pose>0.798891 5.51092 0 0 -0 0</pose>
    </model>
    <model name='apriltag_5'>
      <static>1</static>
      <link name='link'>
        <pose>0 0 0.17 3.14159 1.57079 3.14159</pose>
        <visual name='visual'>
          <geometry>
            <box>
              <size>0.04 0.04 0.001</size>
            </box>
          </geometry>
          <material>
            <script>
              <uri>model://apriltag_5/materials/scripts</uri>
              <uri>model://apriltag_5/materials/textures</uri>
              <name>AprilTag/Tag5</name>
            </script>
          </material>
        </visual>
        <collision name='collision'>
          <geometry>
            <box>
              <size>0.04 0.04 0.001</size>
            </box>
          </geometry>
          <max_contacts>10</max_contacts>
          <surface>
            <contact>
              <ode/>
            </contact>
            <bounce/>
            <friction>
              <torsional>
                <ode/>
              </torsional>
              <ode/>
            </friction>
          </surface>
        </collision>
        <self_collide>0</self_collide>
        <enable_wind>0</enable_wind>
        <kinematic>0</kinematic>
      </link>
      <pose>2.19787 5.68217 0 0 -0 0</pose>
    </model>
    <model name='apriltag_6'>
      <static>1</static>
      <link name='link'>
        <pose>0 0 0.17 3.14159 1.57079 3.14159</pose>
        <visual name='visual'>
          <geometry>
            <box>
              <size>0.04 0.04 0.001</size>
            </box>
          </geometry>
          <material>
            <script>
              <uri>model://apriltag_6/materials/scripts</uri>
              <uri>model://apriltag_6/materials/textures</uri>
              <name>AprilTag/Tag6</name>
            </script>
          </material>
        </visual>
        <collision name='collision'>
          <geometry>
            <box>
              <size>0.04 0.04 0.001</size>
            </box>
          </geometry>
          <max_contacts>10</max_contacts>
          <surface>
            <contact>
              <ode/>
            </contact>
            <bounce/>
            <friction>
              <torsional>
                <ode/>
              </torsional>
              <ode/>
            </friction>
          </surface>
        </collision>
        <self_collide>0</self_collide>
        <enable_wind>0</enable_wind>
        <kinematic>0</kinematic>
      </link>
      <pose>3.39879 5.41894 0 0 -0 0</pose>
    </model>
    <model name='apriltag_7'>
      <static>1</static>
      <link name='link'>
        <pose>0 0 0.17 1.5708 -0 0</pose>
        <visual name='visual'>
          <geometry>
            <box>
              <size>0.04 0.04 0.001</size>
            </box>
          </geometry>
          <material>
            <script>
              <uri>model://apriltag_7/materials/scripts</uri>
              <uri>model://apriltag_7/materials/textures</uri>
              <name>AprilTag/Tag7</name>
            </script>
          </material>
        </visual>
        <collision name='collision'>
          <geometry>
            <box>
              <size>0.04 0.04 0.001</size>
            </box>
          </geometry>
          <max_contacts>10</max_contacts>
          <surface>
            <contact>
              <ode/>
            </contact>
            <bounce/>
            <friction>
              <torsional>
                <ode/>
              </torsional>
              <ode/>
            </friction>
          </surface>
        </collision>
        <self_collide>0</self_collide>
        <enable_wind>0</enable_wind>
        <kinematic>0</kinematic>
      </link>
      <pose>1.40567 4.15006 0 0 -0 0</pose>
    </model>
    <model name='apriltag_8'>
      <static>1</static>
      <link name='link'>
        <pose>0 0 0.17 1.5708 -0 0</pose>
        <visual name='visual'>
          <geometry>
            <box>
              <size>0.04 0.04 0.001</size>
            </box>
          </geometry>
          <material>
            <script>
              <uri>model://apriltag_8/materials/scripts</uri>
              <uri>model://apriltag_8/materials/textures</uri>
              <name>AprilTag/Tag8</name>
            </script>
          </material>
        </visual>
        <collision name='collision'>
          <geometry>
            <box>
              <size>0.04 0.04 0.001</size>
            </box>
          </geometry>
          <max_contacts>10</max_contacts>
          <surface>
            <contact>
              <ode/>
            </contact>
            <bounce/>
            <friction>
              <torsional>
                <ode/>
              </torsional>
              <ode/>
            </friction>
          </surface>
        </collision>
        <self_collide>0</self_collide>
        <enable_wind>0</enable_wind>
        <kinematic>0</kinematic>
      </link>
      <pose>3.61425 4.15086 0 0 -0 0</pose>
    </model>
    <model name='apriltag_9'>
      <static>1</static>
      <link name='link'>
        <pose>0 0 0.17 1.5708 -0 0</pose>
        <visual name='visual'>
          <geometry>
            <box>
              <size>0.04 0.04 0.001</size>
            </box>
          </geometry>
          <material>
            <script>
              <uri>model://apriltag_9/materials/scripts</uri>
              <uri>model://apriltag_9/materials/textures</uri>
              <name>AprilTag/Tag9</name>
            </script>
          </material>
        </visual>
        <collision name='collision'>
          <geometry>
            <box>
              <size>0.04 0.04 0.001</size>
            </box>
          </geometry>
          <max_contacts>10</max_contacts>
          <surface>
            <contact>
              <ode/>
            </contact>
            <bounce/>
            <friction>
              <torsional>
                <ode/>
              </torsional>
              <ode/>
            </friction>
          </surface>
        </collision>
        <self_collide>0</self_collide>
        <enable_wind>0</enable_wind>
        <kinematic>0</kinematic>
      </link>
      <pose>1.30993 3.15197 0 0 -0 0</pose>
    </model>
    <model name='apriltag_10'>
      <static>1</static>
      <link name='link'>
        <pose>0 0 0.17 1.5708 -0 0</pose>
        <visual name='visual'>
          <geometry>
            <box>
              <size>0.04 0.04 0.001</size>
            </box>
          </geometry>
          <material>
            <script>
              <uri>model://apriltag_10/materials/scripts</uri>
              <uri>model://apriltag_10/materials/textures</uri>
              <name>AprilTag/Tag10</name>
            </script>
          </material>
        </visual>
        <collision name='collision'>
          <geometry>
            <box>
              <size>0.04 0.04 0.001</size>
            </box>
          </geometry>
          <max_contacts>10</max_contacts>
          <surface>
            <contact>
              <ode/>
            </contact>
            <bounce/>
            <friction>
              <torsional>
                <ode/>
              </torsional>
              <ode/>
            </friction>
          </surface>
        </collision>
        <self_collide>0</self_collide>
        <enable_wind>0</enable_wind>
        <kinematic>0</kinematic>
      </link>
      <pose>3.47387 3.15119 0 0 -0 0</pose>
    </model>
    <model name='apriltag_11'>
      <static>1</static>
      <link name='link'>
        <pose>0 0 0.17 1.5708 -0 0</pose>
        <visual name='visual'>
          <geometry>
            <box>
              <size>0.04 0.04 0.001</size>
            </box>
          </geometry>
          <material>
            <script>
              <uri>model://apriltag_11/materials/scripts</uri>
              <uri>model://apriltag_11/materials/textures</uri>
              <name>AprilTag/Tag11</name>
            </script>
          </material>
        </visual>
        <collision name='collision'>
          <geometry>
            <box>
              <size>0.04 0.04 0.001</size>
            </box>
          </geometry>
          <max_contacts>10</max_contacts>
          <surface>
            <contact>
              <ode/>
            </contact>
            <bounce/>
            <friction>
              <torsional>
                <ode/>
              </torsional>
              <ode/>
            </friction>
          </surface>
        </collision>
        <self_collide>0</self_collide>
        <enable_wind>0</enable_wind>
        <kinematic>0</kinematic>
      </link>
      <pose>1.21358 2.1504 0 0 -0 0</pose>
    </model>
    <model name='apriltag_12'>
      <static>1</static>
      <link name='link'>
        <pose>0 0 0.17 1.5708 -0 0</pose>
        <visual name='visual'>
          <geometry>
            <box>
              <size>0.04 0.04 0.001</size>
            </box>
          </geometry>
          <material>
            <script>
              <uri>model://apriltag_12/materials/scripts</uri>
              <uri>model://apriltag_12/materials/textures</uri>
              <name>AprilTag/Tag12</name>
            </script>
          </material>
        </visual>
        <collision name='collision'>
          <geometry>
            <box>
              <size>0.04 0.04 0.001</size>
            </box>
          </geometry>
          <max_contacts>10</max_contacts>
          <surface>
            <contact>
              <ode/>
            </contact>
            <bounce/>
            <friction>
              <torsional>
                <ode/>
              </torsional>
              <ode/>
            </friction>
          </surface>
        </collision>
        <self_collide>0</self_collide>
        <enable_wind>0</enable_wind>
        <kinematic>0</kinematic>
      </link>
      <pose>3.64443 2.15148 0 0 -0 0</pose>
    </model>
  </world>
</sdf>
